Workbook

Sheet 📋 DASHBOARD
B1: 🏭 HRBR EXPERIENCE CENTRE — MATERIAL AUDIT TRACKER
B2: Bangalore Location | 3,067 total SKUs
C4: AUDIT 1 | G4: AUDIT 2 | K4: AUDIT 3 | O4: AUDIT 4 | S4: AUDIT 5
B5: Category | C5: Total SKUs | D5: ✓ OK | E5: ⚠ Issues | F5: Done % | G5: Total SKUs | H5: ✓ OK | I5: ⚠ Issues | J5: Done % | K5: Total SKUs | L5: ✓ OK | M5: ⚠ Issues | N5: Done % | O5: Total SKUs | P5: ✓ OK | Q5: ⚠ Issues | R5: Done % | S5: Total SKUs | T5: ✓ OK | U5: ⚠ Issues | V5: Done %
B6: Laminates | C6: 292 | D6: =COUNTIF(Laminates!M5:M288,"✓ OK") -> 256 | E6: =COUNTIF(Laminates!M5:M288,"⚠ Check")+COUNTIF(Laminates!M5:M288,"⚠ Missing")+COUNTIF(Laminates!M5:M288,"❌ Disc") -> 28 | F6: =IFERROR(COUNTIF(Laminates!E5:E288,"<>"&"")/292,"—") -> 0.97260274 | G6: 292 | H6: =COUNTIF(Laminates!V5:V288,"✓ OK") -> 212 | I6: =COUNTIF(Laminates!V5:V288,"⚠ Check")+COUNTIF(Laminates!V5:V288,"⚠ Missing")+COUNTIF(Laminates!V5:V288,"❌ Disc") -> 72 | J6: =IFERROR(COUNTIF(Laminates!N5:N288,"<>"&"")/292,"—") -> 0.97260274 | K6: 292 | L6: =COUNTIF(Laminates!AE5:AE288,"✓ OK") -> 216 | M6: =COUNTIF(Laminates!AE5:AE288,"⚠ Check")+COUNTIF(Laminates!AE5:AE288,"⚠ Missing")+COUNTIF(Laminates!AE5:AE288,"❌ Disc") -> 68 | N6: =IFERROR(COUNTIF(Laminates!W5:W288,"<>"&"")/292,"—") -> 0.97260274 | O6: 292 | P6: =COUNTIF(Laminates!AN5:AN288,"✓ OK") -> 197 | Q6: =COUNTIF(Laminates!AN5:AN288,"⚠ Check")+COUNTIF(Laminates!AN5:AN288,"⚠ Missing")+COUNTIF(Laminates!AN5:AN288,"❌ Disc") -> 87 | R6: =IFERROR(COUNTIF(Laminates!AF5:AF288,"<>"&"")/292,"—") -> 0.97260274 | S6: 292 | T6: =COUNTIF(Laminates!AW5:AW288,"✓ OK") -> 0 | U6: =COUNTIF(Laminates!AW5:AW288,"⚠ Check")+COUNTIF(Laminates!AW5:AW288,"⚠ Missing")+COUNTIF(Laminates!AW5:AW288,"❌ Disc") -> 0 | V6: =IFERROR(COUNTIF(Laminates!AO5:AO288,"<>"&"")/292,"—") -> 0
B7: Acrylic n Crystal Acrylic | C7: 63 | D7: =COUNTIF('Acrylic n Crystal Acrylic'!M5:M67,"✓ OK") -> 63 | E7: =COUNTIF('Acrylic n Crystal Acrylic'!M5:M67,"⚠ Check")+COUNTIF('Acrylic n Crystal Acrylic'!M5:M67,"⚠ Missing")+COUNTIF('Acrylic n Crystal Acrylic'!M5:M67,"❌ Disc") -> 0 | F7: =IFERROR(COUNTIF('Acrylic n Crystal Acrylic'!E5:E67,"<>"&"")/63,"—") -> 1 | G7: 63 | H7: =COUNTIF('Acrylic n Crystal Acrylic'!V5:V67,"✓ OK") -> 63 | I7: =COUNTIF('Acrylic n Crystal Acrylic'!V5:V67,"⚠ Check")+COUNTIF('Acrylic n Crystal Acrylic'!V5:V67,"⚠ Missing")+COUNTIF('Acrylic n Crystal Acrylic'!V5:V67,"❌ Disc") -> 0 | J7: =IFERROR(COUNTIF('Acrylic n Crystal Acrylic'!N5:N67,"<>"&"")/63,"—") -> 1 | K7: 63 | L7: =COUNTIF('Acrylic n Crystal Acrylic'!AE5:AE67,"✓ OK") -> 63 | M7: =COUNTIF('Acrylic n Crystal Acrylic'!AE5:AE67,"⚠ Check")+COUNTIF('Acrylic n Crystal Acrylic'!AE5:AE67,"⚠ Missing")+COUNTIF('Acrylic n Crystal Acrylic'!AE5:AE67,"❌ Disc") -> 0 | N7: =IFERROR(COUNTIF('Acrylic n Crystal Acrylic'!W5:W67,"<>"&"")/63,"—") -> 1 | O7: 63 | P7: =COUNTIF('Acrylic n Crystal Acrylic'!AN5:AN67,"✓ OK") -> 63 | Q7: =COUNTIF('Acrylic n Crystal Acrylic'!AN5:AN67,"⚠ Check")+COUNTIF('Acrylic n Crystal Acrylic'!AN5:AN67,"⚠ Missing")+COUNTIF('Acrylic n Crystal Acrylic'!AN5:AN67,"❌ Disc") -> 0 | R7: =IFERROR(COUNTIF('Acrylic n Crystal Acrylic'!AF5:AF67,"<>"&"")/63,"—") -> 1 | S7: 63 | T7: =COUNTIF('Acrylic n Crystal Acrylic'!AW5:AW67,"✓ OK") -> 0 | U7: =COUNTIF('Acrylic n Crystal Acrylic'!AW5:AW67,"⚠ Check")+COUNTIF('Acrylic n Crystal Acrylic'!AW5:AW67,"⚠ Missing")+COUNTIF('Acrylic n Crystal Acrylic'!AW5:AW67,"❌ Disc") -> 0 | V7: =IFERROR(COUNTIF('Acrylic n Crystal Acrylic'!AO5:AO67,"<>"&"")/63,"—") -> 0
B8: PU and Membrane | C8: 81 | D8: =COUNTIF('PU and Membrane'!M5:M85,"✓ OK") -> 79 | E8: =COUNTIF('PU and Membrane'!M5:M85,"⚠ Check")+COUNTIF('PU and Membrane'!M5:M85,"⚠ Missing")+COUNTIF('PU and Membrane'!M5:M85,"❌ Disc") -> 2 | F8: =IFERROR(COUNTIF('PU and Membrane'!E5:E85,"<>"&"")/81,"—") -> 1 | G8: 81 | H8: =COUNTIF('PU and Membrane'!V5:V85,"✓ OK") -> 79 | I8: =COUNTIF('PU and Membrane'!V5:V85,"⚠ Check")+COUNTIF('PU and Membrane'!V5:V85,"⚠ Missing")+COUNTIF('PU and Membrane'!V5:V85,"❌ Disc") -> 2 | J8: =IFERROR(COUNTIF('PU and Membrane'!N5:N85,"<>"&"")/81,"—") -> 1 | K8: 81 | L8: =COUNTIF('PU and Membrane'!AE5:AE85,"✓ OK") -> 79 | M8: =COUNTIF('PU and Membrane'!AE5:AE85,"⚠ Check")+COUNTIF('PU and Membrane'!AE5:AE85,"⚠ Missing")+COUNTIF('PU and Membrane'!AE5:AE85,"❌ Disc") -> 2 | N8: =IFERROR(COUNTIF('PU and Membrane'!W5:W85,"<>"&"")/81,"—") -> 1 | O8: 81 | P8: =COUNTIF('PU and Membrane'!AN5:AN85,"✓ OK") -> 79 | Q8: =COUNTIF('PU and Membrane'!AN5:AN85,"⚠ Check")+COUNTIF('PU and Membrane'!AN5:AN85,"⚠ Missing")+COUNTIF('PU and Membrane'!AN5:AN85,"❌ Disc") -> 2 | R8: =IFERROR(COUNTIF('PU and Membrane'!AF5:AF85,"<>"&"")/81,"—") -> 1 | S8: 81 | T8: =COUNTIF('PU and Membrane'!AW5:AW85,"✓ OK") -> 0 | U8: =COUNTIF('PU and Membrane'!AW5:AW85,"⚠ Check")+COUNTIF('PU and Membrane'!AW5:AW85,"⚠ Missing")+COUNTIF('PU and Membrane'!AW5:AW85,"❌ Disc") -> 0 | V8: =IFERROR(COUNTIF('PU and Membrane'!AO5:AO85,"<>"&"")/81,"—") -> 0
B9: Rafters | C9: 164 | D9: =COUNTIF(Rafters!M5:M168,"✓ OK") -> 150 | E9: =COUNTIF(Rafters!M5:M168,"⚠ Check")+COUNTIF(Rafters!M5:M168,"⚠ Missing")+COUNTIF(Rafters!M5:M168,"❌ Disc") -> 14 | F9: =IFERROR(COUNTIF(Rafters!E5:E168,"<>"&"")/164,"—") -> 1 | G9: 164 | H9: =COUNTIF(Rafters!V5:V168,"✓ OK") -> 144 | I9: =COUNTIF(Rafters!V5:V168,"⚠ Check")+COUNTIF(Rafters!V5:V168,"⚠ Missing")+COUNTIF(Rafters!V5:V168,"❌ Disc") -> 20 | J9: =IFERROR(COUNTIF(Rafters!N5:N168,"<>"&"")/164,"—") -> 1 | K9: 164 | L9: =COUNTIF(Rafters!AE5:AE168,"✓ OK") -> 144 | M9: =COUNTIF(Rafters!AE5:AE168,"⚠ Check")+COUNTIF(Rafters!AE5:AE168,"⚠ Missing")+COUNTIF(Rafters!AE5:AE168,"❌ Disc") -> 20 | N9: =IFERROR(COUNTIF(Rafters!W5:W168,"<>"&"")/164,"—") -> 1 | O9: 164 | P9: =COUNTIF(Rafters!AN5:AN168,"✓ OK") -> 141 | Q9: =COUNTIF(Rafters!AN5:AN168,"⚠ Check")+COUNTIF(Rafters!AN5:AN168,"⚠ Missing")+COUNTIF(Rafters!AN5:AN168,"❌ Disc") -> 23 | R9: =IFERROR(COUNTIF(Rafters!AF5:AF168,"<>"&"")/164,"—") -> 1 | S9: 164 | T9: =COUNTIF(Rafters!AW5:AW168,"✓ OK") -> 0 | U9: =COUNTIF(Rafters!AW5:AW168,"⚠ Check")+COUNTIF(Rafters!AW5:AW168,"⚠ Missing")+COUNTIF(Rafters!AW5:AW168,"❌ Disc") -> 0 | V9: =IFERROR(COUNTIF(Rafters!AO5:AO168,"<>"&"")/164,"—") -> 0
B10: Wallpaper | C10: 1409 | D10: =COUNTIF(Wallpaper!M5:M1413,"✓ OK") -> 1406 | E10: =COUNTIF(Wallpaper!M5:M1413,"⚠ Check")+COUNTIF(Wallpaper!M5:M1413,"⚠ Missing")+COUNTIF(Wallpaper!M5:M1413,"❌ Disc") -> 3 | F10: =IFERROR(COUNTIF(Wallpaper!E5:E1413,"<>"&"")/1409,"—") -> 1 | G10: 1409 | H10: =COUNTIF(Wallpaper!V5:V1413,"✓ OK") -> 1406 | I10: =COUNTIF(Wallpaper!V5:V1413,"⚠ Check")+COUNTIF(Wallpaper!V5:V1413,"⚠ Missing")+COUNTIF(Wallpaper!V5:V1413,"❌ Disc") -> 3 | J10: =IFERROR(COUNTIF(Wallpaper!N5:N1413,"<>"&"")/1409,"—") -> 1 | K10: 1409 | L10: =COUNTIF(Wallpaper!AE5:AE1413,"✓ OK") -> 1406 | M10: =COUNTIF(Wallpaper!AE5:AE1413,"⚠ Check")+COUNTIF(Wallpaper!AE5:AE1413,"⚠ Missing")+COUNTIF(Wallpaper!AE5:AE1413,"❌ Disc") -> 3 | N10: =IFERROR(COUNTIF(Wallpaper!W5:W1413,"<>"&"")/1409,"—") -> 1 | O10: 1409 | P10: =COUNTIF(Wallpaper!AN5:AN1413,"✓ OK") -> 1406 | Q10: =COUNTIF(Wallpaper!AN5:AN1413,"⚠ Check")+COUNTIF(Wallpaper!AN5:AN1413,"⚠ Missing")+COUNTIF(Wallpaper!AN5:AN1413,"❌ Disc") -> 3 | R10: =IFERROR(COUNTIF(Wallpaper!AF5:AF1413,"<>"&"")/1409,"—") -> 1 | S10: 1409 | T10: =COUNTIF(Wallpaper!AW5:AW1413,"✓ OK") -> 0 | U10: =COUNTIF(Wallpaper!AW5:AW1413,"⚠ Check")+COUNTIF(Wallpaper!AW5:AW1413,"⚠ Missing")+COUNTIF(Wallpaper!AW5:AW1413,"❌ Disc") -> 0 | V10: =IFERROR(COUNTIF(Wallpaper!AO5:AO1413,"<>"&"")/1409,"—") -> 0
B11: Quartz | C11: 113 | D11: =COUNTIF(Quartz!M5:M117,"✓ OK") -> 109 | E11: =COUNTIF(Quartz!M5:M117,"⚠ Check")+COUNTIF(Quartz!M5:M117,"⚠ Missing")+COUNTIF(Quartz!M5:M117,"❌ Disc") -> 4 | F11: =IFERROR(COUNTIF(Quartz!E5:E117,"<>"&"")/113,"—") -> 1 | G11: 113 | H11: =COUNTIF(Quartz!V5:V77,"✓ OK") -> 59 | I11: =COUNTIF(Quartz!V5:V77,"⚠ Check")+COUNTIF(Quartz!V5:V77,"⚠ Missing")+COUNTIF(Quartz!V5:V77,"❌ Disc") -> 14 | J11: =IFERROR(COUNTIF(Quartz!N5:N77,"<>"&"")/73,"—") -> 1 | K11: 113 | L11: =COUNTIF(Quartz!AE5:AE77,"✓ OK") -> 59 | M11: =COUNTIF(Quartz!AE5:AE77,"⚠ Check")+COUNTIF(Quartz!AE5:AE77,"⚠ Missing")+COUNTIF(Quartz!AE5:AE77,"❌ Disc") -> 14 | N11: =IFERROR(COUNTIF(Quartz!W5:W77,"<>"&"")/73,"—") -> 1 | O11: 113 | P11: =COUNTIF(Quartz!AN5:AN77,"✓ OK") -> 59 | Q11: =COUNTIF(Quartz!AN5:AN77,"⚠ Check")+COUNTIF(Quartz!AN5:AN77,"⚠ Missing")+COUNTIF(Quartz!AN5:AN77,"❌ Disc") -> 14 | R11: =IFERROR(COUNTIF(Quartz!AF5:AF77,"<>"&"")/73,"—") -> 1 | S11: 113 | T11: =COUNTIF(Quartz!AW5:AW77,"✓ OK") -> 0 | U11: =COUNTIF(Quartz!AW5:AW77,"⚠ Check")+COUNTIF(Quartz!AW5:AW77,"⚠ Missing")+COUNTIF(Quartz!AW5:AW77,"❌ Disc") -> 0 | V11: =IFERROR(COUNTIF(Quartz!AO5:AO77,"<>"&"")/73,"—") -> 0
B12: Granite | C12: 12 | D12: =COUNTIF(Granite!M5:M16,"✓ OK") -> 10 | E12: =COUNTIF(Granite!M5:M16,"⚠ Check")+COUNTIF(Granite!M5:M16,"⚠ Missing")+COUNTIF(Granite!M5:M16,"❌ Disc") -> 2 | F12: =IFERROR(COUNTIF(Granite!E5:E16,"<>"&"")/12,"—") -> 1 | G12: 12 | H12: =COUNTIF(Granite!V5:V15,"✓ OK") -> 9 | I12: =COUNTIF(Granite!V5:V15,"⚠ Check")+COUNTIF(Granite!V5:V15,"⚠ Missing")+COUNTIF(Granite!V5:V15,"❌ Disc") -> 2 | J12: =IFERROR(COUNTIF(Granite!N5:N15,"<>"&"")/11,"—") -> 1 | K12: 12 | L12: =COUNTIF(Granite!AE5:AE15,"✓ OK") -> 11 | M12: =COUNTIF(Granite!AE5:AE15,"⚠ Check")+COUNTIF(Granite!AE5:AE15,"⚠ Missing")+COUNTIF(Granite!AE5:AE15,"❌ Disc") -> 0 | N12: =IFERROR(COUNTIF(Granite!W5:W15,"<>"&"")/11,"—") -> 1 | O12: 12 | P12: =COUNTIF(Granite!AN5:AN15,"✓ OK") -> 11 | Q12: =COUNTIF(Granite!AN5:AN15,"⚠ Check")+COUNTIF(Granite!AN5:AN15,"⚠ Missing")+COUNTIF(Granite!AN5:AN15,"❌ Disc") -> 0 | R12: =IFERROR(COUNTIF(Granite!AF5:AF15,"<>"&"")/11,"—") -> 1 | S12: 12 | T12: =COUNTIF(Granite!AW5:AW15,"✓ OK") -> 0 | U12: =COUNTIF(Granite!AW5:AW15,"⚠ Check")+COUNTIF(Granite!AW5:AW15,"⚠ Missing")+COUNTIF(Granite!AW5:AW15,"❌ Disc") -> 0 | V12: =IFERROR(COUNTIF(Granite!AO5:AO15,"<>"&"")/11,"—") -> 0
B13: Wooden Flooring | C13: 22 | D13: =COUNTIF('Wooden Flooring'!M5:M26,"✓ OK") -> 17 | E13: =COUNTIF('Wooden Flooring'!M5:M26,"⚠ Check")+COUNTIF('Wooden Flooring'!M5:M26,"⚠ Missing")+COUNTIF('Wooden Flooring'!M5:M26,"❌ Disc") -> 5 | F13: =IFERROR(COUNTIF('Wooden Flooring'!E5:E26,"<>"&"")/22,"—") -> 1 | G13: 22 | H13: =COUNTIF('Wooden Flooring'!V5:V26,"✓ OK") -> 17 | I13: =COUNTIF('Wooden Flooring'!V5:V26,"⚠ Check")+COUNTIF('Wooden Flooring'!V5:V26,"⚠ Missing")+COUNTIF('Wooden Flooring'!V5:V26,"❌ Disc") -> 5 | J13: =IFERROR(COUNTIF('Wooden Flooring'!N5:N26,"<>"&"")/22,"—") -> 1 | K13: 22 | L13: =COUNTIF('Wooden Flooring'!AE5:AE26,"✓ OK") -> 17 | M13: =COUNTIF('Wooden Flooring'!AE5:AE26,"⚠ Check")+COUNTIF('Wooden Flooring'!AE5:AE26,"⚠ Missing")+COUNTIF('Wooden Flooring'!AE5:AE26,"❌ Disc") -> 5 | N13: =IFERROR(COUNTIF('Wooden Flooring'!W5:W26,"<>"&"")/22,"—") -> 1 | O13: 22 | P13: =COUNTIF('Wooden Flooring'!AN5:AN26,"✓ OK") -> 17 | Q13: =COUNTIF('Wooden Flooring'!AN5:AN26,"⚠ Check")+COUNTIF('Wooden Flooring'!AN5:AN26,"⚠ Missing")+COUNTIF('Wooden Flooring'!AN5:AN26,"❌ Disc") -> 5 | R13: =IFERROR(COUNTIF('Wooden Flooring'!AF5:AF26,"<>"&"")/22,"—") -> 1 | S13: 22 | T13: =COUNTIF('Wooden Flooring'!AW5:AW26,"✓ OK") -> 0 | U13: =COUNTIF('Wooden Flooring'!AW5:AW26,"⚠ Check")+COUNTIF('Wooden Flooring'!AW5:AW26,"⚠ Missing")+COUNTIF('Wooden Flooring'!AW5:AW26,"❌ Disc") -> 0 | V13: =IFERROR(COUNTIF('Wooden Flooring'!AO5:AO26,"<>"&"")/22,"—") -> 0
B14: Beading | C14: 35 | D14: =COUNTIF(Beading!M5:M39,"✓ OK") -> 35 | E14: =COUNTIF(Beading!M5:M39,"⚠ Check")+COUNTIF(Beading!M5:M39,"⚠ Missing")+COUNTIF(Beading!M5:M39,"❌ Disc") -> 0 | F14: =IFERROR(COUNTIF(Beading!E5:E39,"<>"&"")/35,"—") -> 1 | G14: 35 | H14: =COUNTIF(Beading!V5:V39,"✓ OK") -> 35 | I14: =COUNTIF(Beading!V5:V39,"⚠ Check")+COUNTIF(Beading!V5:V39,"⚠ Missing")+COUNTIF(Beading!V5:V39,"❌ Disc") -> 0 | J14: =IFERROR(COUNTIF(Beading!N5:N39,"<>"&"")/35,"—") -> 1 | K14: 35 | L14: =COUNTIF(Beading!AE5:AE39,"✓ OK") -> 35 | M14: =COUNTIF(Beading!AE5:AE39,"⚠ Check")+COUNTIF(Beading!AE5:AE39,"⚠ Missing")+COUNTIF(Beading!AE5:AE39,"❌ Disc") -> 0 | N14: =IFERROR(COUNTIF(Beading!W5:W39,"<>"&"")/35,"—") -> 1 | O14: 35 | P14: =COUNTIF(Beading!AN5:AN39,"✓ OK") -> 35 | Q14: =COUNTIF(Beading!AN5:AN39,"⚠ Check")+COUNTIF(Beading!AN5:AN39,"⚠ Missing")+COUNTIF(Beading!AN5:AN39,"❌ Disc") -> 0 | R14: =IFERROR(COUNTIF(Beading!AF5:AF39,"<>"&"")/35,"—") -> 1 | S14: 35 | T14: =COUNTIF(Beading!AW5:AW39,"✓ OK") -> 0 | U14: =COUNTIF(Beading!AW5:AW39,"⚠ Check")+COUNTIF(Beading!AW5:AW39,"⚠ Missing")+COUNTIF(Beading!AW5:AW39,"❌ Disc") -> 0 | V14: =IFERROR(COUNTIF(Beading!AO5:AO39,"<>"&"")/35,"—") -> 0
B15: Bonito Legs | C15: 76 | D15: =COUNTIF('Bonito Legs'!M5:M80,"✓ OK") -> 76 | E15: =COUNTIF('Bonito Legs'!M5:M80,"⚠ Check")+COUNTIF('Bonito Legs'!M5:M80,"⚠ Missing")+COUNTIF('Bonito Legs'!M5:M80,"❌ Disc") -> 0 | F15: =IFERROR(COUNTIF('Bonito Legs'!E5:E80,"<>"&"")/76,"—") -> 1 | G15: 76 | H15: =COUNTIF('Bonito Legs'!V5:V80,"✓ OK") -> 76 | I15: =COUNTIF('Bonito Legs'!V5:V80,"⚠ Check")+COUNTIF('Bonito Legs'!V5:V80,"⚠ Missing")+COUNTIF('Bonito Legs'!V5:V80,"❌ Disc") -> 0 | J15: =IFERROR(COUNTIF('Bonito Legs'!N5:N80,"<>"&"")/76,"—") -> 1 | K15: 76 | L15: =COUNTIF('Bonito Legs'!AE5:AE80,"✓ OK") -> 76 | M15: =COUNTIF('Bonito Legs'!AE5:AE80,"⚠ Check")+COUNTIF('Bonito Legs'!AE5:AE80,"⚠ Missing")+COUNTIF('Bonito Legs'!AE5:AE80,"❌ Disc") -> 0 | N15: =IFERROR(COUNTIF('Bonito Legs'!W5:W80,"<>"&"")/76,"—") -> 1 | O15: 76 | P15: =COUNTIF('Bonito Legs'!AN5:AN80,"✓ OK") -> 76 | Q15: =COUNTIF('Bonito Legs'!AN5:AN80,"⚠ Check")+COUNTIF('Bonito Legs'!AN5:AN80,"⚠ Missing")+COUNTIF('Bonito Legs'!AN5:AN80,"❌ Disc") -> 0 | R15: =IFERROR(COUNTIF('Bonito Legs'!AF5:AF80,"<>"&"")/76,"—") -> 1 | S15: 76 | T15: =COUNTIF('Bonito Legs'!AW5:AW80,"✓ OK") -> 0 | U15: =COUNTIF('Bonito Legs'!AW5:AW80,"⚠ Check")+COUNTIF('Bonito Legs'!AW5:AW80,"⚠ Missing")+COUNTIF('Bonito Legs'!AW5:AW80,"❌ Disc") -> 0 | V15: =IFERROR(COUNTIF('Bonito Legs'!AO5:AO80,"<>"&"")/76,"—") -> 0
B16: Handles | C16: 512 | D16: =COUNTIF(Handles!M5:M516,"✓ OK") -> 396 | E16: =COUNTIF(Handles!M5:M516,"⚠ Check")+COUNTIF(Handles!M5:M516,"⚠ Missing")+COUNTIF(Handles!M5:M516,"❌ Disc") -> 116 | F16: =IFERROR(COUNTIF(Handles!E5:E516,"<>"&"")/512,"—") -> 1 | G16: 512 | H16: =COUNTIF(Handles!V5:V516,"✓ OK") -> 396 | I16: =COUNTIF(Handles!V5:V516,"⚠ Check")+COUNTIF(Handles!V5:V516,"⚠ Missing")+COUNTIF(Handles!V5:V516,"❌ Disc") -> 116 | J16: =IFERROR(COUNTIF(Handles!N5:N516,"<>"&"")/512,"—") -> 1 | K16: 512 | L16: =COUNTIF(Handles!AE5:AE516,"✓ OK") -> 394 | M16: =COUNTIF(Handles!AE5:AE516,"⚠ Check")+COUNTIF(Handles!AE5:AE516,"⚠ Missing")+COUNTIF(Handles!AE5:AE516,"❌ Disc") -> 118 | N16: =IFERROR(COUNTIF(Handles!W5:W516,"<>"&"")/512,"—") -> 1 | O16: 512 | P16: =COUNTIF(Handles!AN5:AN516,"✓ OK") -> 402 | Q16: =COUNTIF(Handles!AN5:AN516,"⚠ Check")+COUNTIF(Handles!AN5:AN516,"⚠ Missing")+COUNTIF(Handles!AN5:AN516,"❌ Disc") -> 110 | R16: =IFERROR(COUNTIF(Handles!AF5:AF516,"<>"&"")/512,"—") -> 1 | S16: 512 | T16: =COUNTIF(Handles!AW5:AW516,"✓ OK") -> 0 | U16: =COUNTIF(Handles!AW5:AW516,"⚠ Check")+COUNTIF(Handles!AW5:AW516,"⚠ Missing")+COUNTIF(Handles!AW5:AW516,"❌ Disc") -> 0 | V16: =IFERROR(COUNTIF(Handles!AO5:AO516,"<>"&"")/512,"—") -> 0
B17: Fabric | C17: 288 | D17: =COUNTIF(Fabric!M5:M292,"✓ OK") -> 288 | E17: =COUNTIF(Fabric!M5:M292,"⚠ Check")+COUNTIF(Fabric!M5:M292,"⚠ Missing")+COUNTIF(Fabric!M5:M292,"❌ Disc") -> 0 | F17: =IFERROR(COUNTIF(Fabric!E5:E292,"<>"&"")/288,"—") -> 1 | G17: 288 | H17: =COUNTIF(Fabric!V5:V292,"✓ OK") -> 248 | I17: =COUNTIF(Fabric!V5:V292,"⚠ Check")+COUNTIF(Fabric!V5:V292,"⚠ Missing")+COUNTIF(Fabric!V5:V292,"❌ Disc") -> 40 | J17: =IFERROR(COUNTIF(Fabric!N5:N292,"<>"&"")/486,"—") -> 0.59259259 | K17: 288 | L17: =COUNTIF(Fabric!AE5:AE292,"✓ OK") -> 248 | M17: =COUNTIF(Fabric!AE5:AE292,"⚠ Check")+COUNTIF(Fabric!AE5:AE292,"⚠ Missing")+COUNTIF(Fabric!AE5:AE292,"❌ Disc") -> 40 | N17: =IFERROR(COUNTIF(Fabric!W5:W292,"<>"&"")/486,"—") -> 0.59259259 | O17: 288 | P17: =COUNTIF(Fabric!AN5:AN292,"✓ OK") -> 248 | Q17: =COUNTIF(Fabric!AN5:AN292,"⚠ Check")+COUNTIF(Fabric!AN5:AN292,"⚠ Missing")+COUNTIF(Fabric!AN5:AN292,"❌ Disc") -> 40 | R17: =IFERROR(COUNTIF(Fabric!AF5:AF292,"<>"&"")/486,"—") -> 0.59259259 | S17: 288 | T17: =COUNTIF(Fabric!AW5:AW292,"✓ OK") -> 0 | U17: =COUNTIF(Fabric!AW5:AW292,"⚠ Check")+COUNTIF(Fabric!AW5:AW292,"⚠ Missing")+COUNTIF(Fabric!AW5:AW292,"❌ Disc") -> 0 | V17: =IFERROR(COUNTIF(Fabric!AO5:AO292,"<>"&"")/486,"—") -> 0
B18: TOTAL: 3,067 SKUs across 12 categories
B20: HOW TO USE ▼
B21: 1. Click a category tab (e.g. 'Laminates') to open that sheet
B22: 2. Each sheet has 5 AUDIT blocks — fill Audit 1 now, Audit 2 next time, and so on
B23: 3. Always enter AUDIT DATE and AUDITOR NAME at the start of each audit block
B24: 4. Yellow cells = Comments/Remarks — type your notes here
B25: 5. Status auto-updates: ✓ OK (green) | ⚠ Check (yellow) | ⚠ Missing / ❌ Disc (red)
B26: 6. This Dashboard auto-counts OK, Issues and % completion per audit round

Sheet Laminates
A1: 📋 HRBR EC — LAMINATES | Multi-Round Audit Tracker
A2: ➤ Fill AUDIT DATE & AUDITOR first in each block | Yellow = Comments | Status auto-updates | Next audit → use next block
E3: AUDIT 1 | N3: AUDIT 2 | W3: AUDIT 3 | AF3: AUDIT 4 | AO3: AUDIT 5
A4: # | B4: ERP Code | C4: Material / Studio Name | D4: Brand | E4: Audit Date | F4: Auditor | G4: Sample in EC? | H4: Discontinued by Vendor? | I4: Visual Condition | J4: Conformance (Yes/No) | K4: COMMENTS / REMARKS | L4: Follow-Up Action | M4: Status | N4: Audit Date | O4: Auditor | P4: Sample in EC? | Q4: Discontinued by Vendor? | R4: Visual Condition | S4: Conformance (Yes/No) | T4: COMMENTS / REMARKS | U4: Follow-Up Action | V4: Status | W4: Audit Date | X4: Auditor | Y4: Sample in EC? | Z4: Discontinued by Vendor? | AA4: Visual Condition | AB4: Conformance (Yes/No) | AC4: COMMENTS / REMARKS | AD4: Follow-Up Action | AE4: Status | AF4: Audit Date | AG4: Auditor | AH4: Sample in EC? | AI4: Discontinued by Vendor? | AJ4: Visual Condition | AK4: Conformance (Yes/No) | AL4: COMMENTS / REMARKS | AM4: Follow-Up Action | AN4: Status | AO4: Audit Date | AP4: Auditor | AQ4: Sample in EC? | AR4: Discontinued by Vendor? | AS4: Visual Condition | AT4: Conformance (Yes/No) | AU4: COMMENTS / REMARKS | AV4: Follow-Up Action | AW4: Status
A5: 1 | B5: BD-LAM-2024-0106 | C5: Calacatta Art - 1540 MI(Diamond) | D5: Century Laminates | E5: 46125 | F5: Sunil CR | G5: Yes | H5: No | I5: Good finish | J5: Yes | L5: No | M5: =IF(E5="","",IF(H5="Yes","❌ Disc",IF(G5="No","⚠ Missing",IF(J5="Yes","✓ OK","⚠ Check")))) -> ✓ OK | N5: 46193 | O5: Sunil CR | P5: No | Q5: Yes | R5: Discontinued | S5: No | U5: No | V5: =IF(N5="","",IF(Q5="Yes","❌ Disc",IF(P5="No","⚠ Missing",IF(S5="Yes","✓ OK","⚠ Check")))) -> ❌ Disc | W5: 46248 | X5: Sunil CR | Y5: No | Z5: Yes | AA5: Discontinued | AB5: No | AD5: No | AE5: =IF(W5="","",IF(Z5="Yes","❌ Disc",IF(Y5="No","⚠ Missing",IF(AB5="Yes","✓ OK","⚠ Check")))) -> ❌ Disc | AF5: 18-09-2026 | AG5: Sunil CR | AH5: No | AI5: Yes | AJ5: Discontinued | AK5: No | AM5: No | AN5: =IF(AF5="","",IF(AI5="Yes","❌ Disc",IF(AH5="No","⚠ Missing",IF(AK5="Yes","✓ OK","⚠ Check")))) -> ❌ Disc | AW5: =IF(AO5="","",IF(AR5="Yes","❌ Disc",IF(AQ5="No","⚠ Missing",IF(AT5="Yes","✓ OK","⚠ Check"))))
A6: 2 | B6: BD-LAM-2024-0107 | C6: Delight Insignia - 1562 MI(Diamond) | D6: Century Laminates | E6: 46125 | F6: Sunil CR | G6: Yes | H6: No | I6: Good finish | J6: Yes | L6: No | M6: =IF(E6="","",IF(H6="Yes","❌ Disc",IF(G6="No","⚠ Missing",IF(J6="Yes","✓ OK","⚠ Check")))) -> ✓ OK | N6: 46193 | O6: Sunil CR | P6: No | Q6: Yes | R6: Discontinued | S6: No | U6: No | V6: =IF(N6="","",IF(Q6="Yes","❌ Disc",IF(P6="No","⚠ Missing",IF(S6="Yes","✓ OK","⚠ Check")))) -> ❌ Disc | W6: 46248 | X6: Sunil CR | Y6: No | Z6: Yes | AA6: Discontinued | AB6: No | AD6: No | AE6: =IF(W6="","",IF(Z6="Yes","❌ Disc",IF(Y6="No","⚠ Missing",IF(AB6="Yes","✓ OK","⚠ Check")))) -> ❌ Disc | AF6: 18-09-2026 | AG6: Sunil CR | AH6: No | AI6: Yes | AJ6: Discontinued | AK6: No | AM6: No | AN6: =IF(AF6="","",IF(AI6="Yes","❌ Disc",IF(AH6="No","⚠ Missing",IF(AK6="Yes","✓ OK","⚠ Check")))) -> ❌ Disc | AW6: =IF(AO6="","",IF(AR6="Yes","❌ Disc",IF(AQ6="No","⚠ Missing",IF(AT6="Yes","✓ OK","⚠ Check"))))
A7: 3 | B7: BD-LAM-2023-0039 | C7: Lavante Royale - 1543 MI(Diamond) | D7: Century Laminates | E7: 46125 | F7: Sunil CR | G7: Yes | H7: No | I7: Good finish | J7: Yes | L7: No | M7: =IF(E7="","",IF(H7="Yes","❌ Disc",IF(G7="No","⚠ Missing",IF(J7="Yes","✓ OK","⚠ Check")))) -> ✓ OK | N7: 46193 | O7: Sunil CR | P7: No | Q7: Yes | R7: Discontinued | S7: No | U7: No | V7: =IF(N7="","",IF(Q7="Yes","❌ Disc",IF(P7="No","⚠ Missing",IF(S7="Yes","✓ OK","⚠ Check")))) -> ❌ Disc | W7: 46248 | X7: Sunil CR | Y7: No | Z7: Yes | AA7: Discontinued | AB7: No | AD7: No | AE7: =IF(W7="","",IF(Z7="Yes","❌ Disc",IF(Y7="No","⚠ Missing",IF(AB7="Yes","✓ OK","⚠ Check")))) -> ❌ Disc | AF7: 18-09-2026 | AG7: Sunil CR | AH7: No | AI7: Yes | AJ7: Discontinued | AK7: No | AM7: No | AN7: =IF(AF7="","",IF(AI7="Yes","❌ Disc",IF(AH7="No","⚠ Missing",IF(AK7="Yes","✓ OK","⚠ Check")))) -> ❌ Disc | AW7: =IF(AO7="","",IF(AR7="Yes","❌ Disc",IF(AQ7="No","⚠ Missing",IF(AT7="Yes","✓ OK","⚠ Check"))))
A8: 4 | B8: BD-LAM-2024-0105 | C8: Rojo Art - 1539 MI(Diamond) | D8: Century Laminates | E8: 46125 | F8: Sunil CR | G8: Yes | H8: No | I8: Good finish | J8: Yes | L8: No | M8: =IF(E8="","",IF(H8="Yes","❌ Disc",IF(G8="No","⚠ Missing",IF(J8="Yes","✓ OK","⚠ Check")))) -> ✓ OK | N8: 46193 | O8: Sunil CR | P8: No | Q8: Yes | R8: Discontinued | S8: No | U8: No | V8: =IF(N8="","",IF(Q8="Yes","❌ Disc",IF(P8="No","⚠ Missing",IF(S8="Yes","✓ OK","⚠ Check")))) -> ❌ Disc | W8: 46248 | X8: Sunil CR | Y8: No | Z8: Yes | AA8: Discontinued | AB8: No | AD8: No | AE8: =IF(W8="","",IF(Z8="Yes","❌ Disc",IF(Y8="No","⚠ Missing",IF(AB8="Yes","✓ OK","⚠ Check")))) -> ❌ Disc | AF8: 18-09-2026 | AG8: Sunil CR | AH8: No | AI8: Yes | AJ8: Discontinued | AK8: No | AM8: No | AN8: =IF(AF8="","",IF(AI8="Yes","❌ Disc",IF(AH8="No","⚠ Missing",IF(AK8="Yes","✓ OK","⚠ Check")))) -> ❌ Disc | AW8: =IF(AO8="","",IF(AR8="Yes","❌ Disc",IF(AQ8="No","⚠ Missing",IF(AT8="Yes","✓ OK","⚠ Check"))))
A9: 5 | B9: BD-LAM-2024-0104 | C9: Sicilian Art - 1538 MI(Diamond) | D9: Century Laminates | E9: 46125 | F9: Sunil CR | G9: Yes | H9: No | I9: Good finish | J9: Yes | L9: No | M9: =IF(E9="","",IF(H9="Yes","❌ Disc",IF(G9="No","⚠ Missing",IF(J9="Yes","✓ OK","⚠ Check")))) -> ✓ OK | N9: 46193 | O9: Sunil CR | P9: No | Q9: Yes | R9: Discontinued | S9: No | U9: No | V9: =IF(N9="","",IF(Q9="Yes","❌ Disc",IF(P9="No","⚠ Missing",IF(S9="Yes","✓ OK","⚠ Check")))) -> ❌ Disc | W9: 46248 | X9: Sunil CR | Y9: No | Z9: Yes | AA9: Discontinued | AB9: No | AD9: No | AE9: =IF(W9="","",IF(Z9="Yes","❌ Disc",IF(Y9="No","⚠ Missing",IF(AB9="Yes","✓ OK","⚠ Check")))) -> ❌ Disc | AF9: 18-09-2026 | AG9: Sunil CR | AH9: No | AI9: Yes | AJ9: Discontinued | AK9: No | AM9: No | AN9: =IF(AF9="","",IF(AI9="Yes","❌ Disc",IF(AH9="No","⚠ Missing",IF(AK9="Yes","✓ OK","⚠ Check")))) -> ❌ Disc | AW9: =IF(AO9="","",IF(AR9="Yes","❌ Disc",IF(AQ9="No","⚠ Missing",IF(AT9="Yes","✓ OK","⚠ Check"))))
A10: 6 | B10: Lam GL 5373 ARA | C10: Aspen Oak(Platinum) | D10: GREENLAM | E10: 46125 | F10: Sunil CR | G10: Yes | H10: No | I10: Good finish | J10: Yes | L10: No | M10: =IF(E10="","",IF(H10="Yes","❌ Disc",IF(G10="No","⚠ Missing",IF(J10="Yes","✓ OK","⚠ Check")))) -> ✓ OK | N10: 46193 | O10: Sunil CR | P10: Yes | Q10: No | R10: Good finish | S10: Yes | U10: No | V10: =IF(N10="","",IF(Q10="Yes","❌ Disc",IF(P10="No","⚠ Missing",IF(S10="Yes","✓ OK","⚠ Check")))) -> ✓ OK | W10: 46248 | X10: Sunil CR | Y10: Yes | Z10: No | AA10: Good finish | AB10: Yes | AD10: No | AE10: =IF(W10="","",IF(Z10="Yes","❌ Disc",IF(Y10="No","⚠ Missing",IF(AB10="Yes","✓ OK","⚠ Check")))) -> ✓ OK | AF10: 18-09-2026 | AG10: Sunil CR | AH10: Yes | AI10: No | AJ10: Good finish | AK10: Yes | AM10: No | AN10: =IF(AF10="","",IF(AI10="Yes","❌ Disc",IF(AH10="No","⚠ Missing",IF(AK10="Yes","✓ OK","⚠ Check")))) -> ✓ OK | AW10: =IF(AO10="","",IF(AR10="Yes","❌ Disc",IF(AQ10="No","⚠ Missing",IF(AT10="Yes","✓ OK","⚠ Check"))))
A11: 7 | B11: Lam GL 5575 SGL | C11: Black Marmor(Platinum) | D11: GREENLAM | E11: 46125 | F11: Sunil CR | G11: Yes | H11: No | I11: Good finish | J11: Yes | L11: No | M11: =IF(E11="","",IF(H11="Yes","❌ Disc",IF(G11="No","⚠ Missing",IF(J11="Yes","✓ OK","⚠ Check")))) -> ✓ OK | N11: 46193 | O11: Sunil CR | P11: Yes | Q11: No | R11: Good finish | S11: Yes | U11: No | V11: =IF(N11="","",IF(Q11="Yes","❌ Disc",IF(P11="No","⚠ Missing",IF(S11="Yes","✓ OK","⚠ Check")))) -> ✓ OK | W11: 46248 | X11: Sunil CR | Y11: Yes | Z11: No | AA11: Good finish | AB11: Yes | AD11: No | AE11: =IF(W11="","",IF(Z11="Yes","❌ Disc",IF(Y11="No","⚠ Missing",IF(AB11="Yes","✓ OK","⚠ Check")))) -> ✓ OK | AF11: 18-09-2026 | AG11: Sunil CR | AH11: Yes | AI11: No | AJ11: Good finish | AK11: Yes | AM11: No | AN11: =IF(AF11="","",IF(AI11="Yes","❌ Disc",IF(AH11="No","⚠ Missing",IF(AK11="Yes","✓ OK","⚠ Check")))) -> ✓ OK | AW11: =IF(AO11="","",IF(AR11="Yes","❌ Disc",IF(AQ11="No","⚠ Missing",IF(AT11="Yes","✓ OK","⚠ Check"))))
A12: 8 | B12: Lam GL 401 SGL | C12: Black(Platinum) | D12: GREENLAM | E12: 46125 | F12: Sunil CR | G12: Yes | H12: No | I12: Good finish | J12: Yes | L12: No | M12: =IF(E12="","",IF(H12="Yes","❌ Disc",IF(G12="No","⚠ Missing",IF(J12="Yes","✓ OK","⚠ Check")))) -> ✓ OK | N12: 46193 | O12: Sunil CR | P12: Yes | Q12: No | R12: Good finish | S12: Yes | U12: No | V12: =IF(N12="","",IF(Q12="Yes","❌ Disc",IF(P12="No","⚠ Missing",IF(S12="Yes","✓ OK","⚠ Check")))) -> ✓ OK | W12: 46248 | X12: Sunil CR | Y12: Yes | Z12: No | AA12: Good finish | AB12: Yes | AD12: No | AE12: =IF(W12="","",IF(Z12="Yes","❌ Disc",IF(Y12="No","⚠ Missing",IF(AB12="Yes","✓ OK","⚠ Check")))) -> ✓ OK | AF12: 18-09-2026 | AG12: Sunil CR | AH12: Yes | AI12: No | AJ12: Good finish | AK12: Yes | AM12: No | AN12: =IF(AF12="","",IF(AI12="Yes","❌ Disc",IF(AH12="No","⚠ Missing",IF(AK12="Yes","✓ OK","⚠ Check")))) -> ✓ OK | AW12: =IF(AO12="","",IF(AR12="Yes","❌ Disc",IF(AQ12="No","⚠ Missing",IF(AT12="Yes","✓ OK","⚠ Check"))))
A13: 9 | B13: Lam GL 181 SUD | C13: Chocolate(Gold) | D13: GREENLAM | E13: 46125 | F13: Sunil CR | G13: Yes | H13: No | I13: Good finish | J13: Yes | L13: No | M13: =IF(E13="","",IF(H13="Yes","❌ Disc",IF(G13="No","⚠ Missing",IF(J13="Yes","✓ OK","⚠ Check")))) -> ✓ OK | N13: 46193 | O13: Sunil CR | P13: Yes | Q13: No | R13: Good finish | S13: Yes | U13: No | V13: =IF(N13="","",IF(Q13="Yes","❌ Disc",IF(P13="No","⚠ Missing",IF(S13="Yes","✓ OK","⚠ Check")))) -> ✓ OK | W13: 46248 | X13: Sunil CR | Y13: Yes | Z13: No | AA13: Good finish | AB13: Yes | AD13: No | AE13: =IF(W13="","",IF(Z13="Yes","❌ Disc",IF(Y13="No","⚠ Missing",IF(AB13="Yes","✓ OK","⚠ Check")))) -> ✓ OK | AF13: 18-09-2026 | AG13: Sunil CR | AH13: Yes | AI13: No | AJ13: Good finish | AK13: Yes | AM13: No | AN13: =IF(AF13="","",IF(AI13="Yes","❌ Disc",IF(AH13="No","⚠ Missing",IF(AK13="Yes","✓ OK","⚠ Check")))) -> ✓ OK | AW13: =IF(AO13="","",IF(AR13="Yes","❌ Disc",IF(AQ13="No","⚠ Missing",IF(AT13="Yes","✓ OK","⚠ Check"))))
A14: 10 | B14: Lam GL 5571 STN | C14: Creme Marquina(Platinum) | D14: GREENLAM | E14: 46125 | F14: Sunil CR | G14: Yes | H14: No | I14: Good finish | J14: Yes | L14: No | M14: =IF(E14="","",IF(H14="Yes","❌ Disc",IF(G14="No","⚠ Missing",IF(J14="Yes","✓ OK","⚠ Check")))) -> ✓ OK | N14: 46193 | O14: Sunil CR | P14: Yes | Q14: No | R14: Good finish | S14: Yes | U14: No | V14: =IF(N14="","",IF(Q14="Yes","❌ Disc",IF(P14="No","⚠ Missing",IF(S14="Yes","✓ OK","⚠ Check")))) -> ✓ OK | W14: 46248 | X14: Sunil CR | Y14: Yes | Z14: No | AA14: Good finish | AB14: Yes | AD14: No | AE14: =IF(W14="","",IF(Z14="Yes","❌ Disc",IF(Y14="No","⚠ Missing",IF(AB14="Yes","✓ OK","⚠ Check")))) -> ✓ OK | AF14: 18-09-2026 | AG14: Sunil CR | AH14: Yes | AI14: No | AJ14: Good finish | AK14: Yes | AM14: No | AN14: =IF(AF14="","",IF(AI14="Yes","❌ Disc",IF(AH14="No","⚠ Missing",IF(AK14="Yes","✓ OK","⚠ Check")))) -> ✓ OK | AW14: =IF(AO14="","",IF(AR14="Yes","❌ Disc",IF(AQ14="No","⚠ Missing",IF(AT14="Yes","✓ OK","⚠ Check"))))
A15: 11 | B15: Lam GL 361 SGL | C15: Golf Green(Platinum) | D15: GREENLAM | E15: 46125 | F15: Sunil CR | G15: Yes | H15: No | I15: Good finish | J15: Yes | L15: No | M15: =IF(E15="","",IF(H15="Yes","❌ Disc",IF(G15="No","⚠ Missing",IF(J15="Yes","✓ OK","⚠ Check")))) -> ✓ OK | N15: 46193 | O15: Sunil CR | P15: Yes | Q15: No | R15: Good finish | S15: Yes | U15: No | V15: =IF(N15="","",IF(Q15="Yes","❌ Disc",IF(P15="No","⚠ Missing",IF(S15="Yes","✓ OK","⚠ Check")))) -> ✓ OK | W15: 46248 | X15: Sunil CR | Y15: Yes | Z15: No | AA15: Good finish | AB15: Yes | AD15: No | AE15: =IF(W15="","",IF(Z15="Yes","❌ Disc",IF(Y15="No","⚠ Missing",IF(AB15="Yes","✓ OK","⚠ Check")))) -> ✓ OK | AF15: 18-09-2026 | AG15: Sunil CR | AH15: Yes | AI15: No | AJ15: Good finish | AK15: Yes | AM15: No | AN15: =IF(AF15="","",IF(AI15="Yes","❌ Disc",IF(AH15="No","⚠ Missing",IF(AK15="Yes","✓ OK","⚠ Check")))) -> ✓ OK | AW15: =IF(AO15="","",IF(AR15="Yes","❌ Disc",IF(AQ15="No","⚠ Missing",IF(AT15="Yes","✓ OK","⚠ Check"))))
A16: 12 | B16: Lam GL 5372 SUD | C16: Grey Magic(Gold) | D16: GREENLAM | E16: 46125 | F16: Sunil CR | G16: Yes | H16: No | I16: Good finish | J16: Yes | L16: No | M16: =IF(E16="","",IF(H16="Yes","❌ Disc",IF(G16="No","⚠ Missing",IF(J16="Yes","✓ OK","⚠ Check")))) -> ✓ OK | N16: 46193 | O16: Sunil CR | P16: Yes | Q16: No | R16: Good finish | S16: Yes | U16: No | V16: =IF(N16="","",IF(Q16="Yes","❌ Disc",IF(P16="No","⚠ Missing",IF(S16="Yes","✓ OK","⚠ Check")))) -> ✓ OK | W16: 46248 | X16: Sunil CR | Y16: Yes | Z16: No | AA16: Good finish | AB16: Yes | AD16: No | AE16: =IF(W16="","",IF(Z16="Yes","❌ Disc",IF(Y16="No","⚠ Missing",IF(AB16="Yes","✓ OK","⚠ Check")))) -> ✓ OK | AF16: 18-09-2026 | AG16: Sunil CR | AH16: Yes | AI16: No | AJ16: Good finish | AK16: Yes | AM16: No | AN16: =IF(AF16="","",IF(AI16="Yes","❌ Disc",IF(AH16="No","⚠ Missing",IF(AK16="Yes","✓ OK","⚠ Check")))) -> ✓ OK | AW16: =IF(AO16="","",IF(AR16="Yes","❌ Disc",IF(AQ16="No","⚠ Missing",IF(AT16="Yes","✓ OK","⚠ Check"))))
... A48: 44 | B48: Lam GL 693 SUD | C48: Vancouver Maple(Gold) | D48: GREENLAM | E48: 46125 | F48: Sunil CR | G48: Yes | H48: No | I48: Good finish | J48: Yes | L48: No | M48: =IF(E48="","",IF(H48="Yes","❌ Disc",IF(G48="No","⚠ Missing",IF(J48="Yes","✓ OK","⚠ Check")))) -> ✓ OK | N48: 46193 | O48: Sunil CR | P48: Yes | Q48: No | R48: Good finish | S48: Yes | U48: No | V48: =IF(N48="","",IF(Q48="Yes","❌ Disc",IF(P48="No","⚠ Missing",IF(S48="Yes","✓ OK","⚠ Check")))) -> ✓ OK | W48: 46248 | X48: Sunil CR | Y48: Yes | Z48: No | AA48: Good finish | AB48: Yes | AD48: No | AE48: =IF(W48="","",IF(Z48="Yes","❌ Disc",IF(Y48="No","⚠ Missing",IF(AB48="Yes","✓ OK","⚠ Check")))) -> ✓ OK | AF48: 18-09-2026 | AG48: Sunil CR | AH48: Yes | AI48: No | AJ48: Good finish | AK48: Yes | AM48: No | AN48: =IF(AF48="","",IF(AI48="Yes","❌ Disc",IF(AH48="No","⚠ Missing",IF(AK48="Yes","✓ OK","⚠ Check")))) -> ✓ OK | AW48: =IF(AO48="","",IF(AR48="Yes","❌ Disc",IF(AQ48="No","⚠ Missing",IF(AT48="Yes","✓ OK","⚠ Check"))))
A49: 53 | B49: BD-LAM-2024-0003 | C49: Royal Touch - RT Crystal Z+ PP 1123 1.25mm(Diamond) | D49: Royal Touche | E49: 46125 | F49: Sunil CR | G49: Yes | H49: No | I49: Minor defect | J49: No | K49: Categorization sticker is missing | L49: Yes | M49: =IF(E49="","",IF(H49="Yes","❌ Disc",IF(G49="No","⚠ Missing",IF(J49="Yes","✓ OK","⚠ Check")))) -> ⚠ Check | N49: 46193 | O49: Sunil CR | P49: Yes | Q49: No | R49: Minor defect | S49: No | T49: Categorization sticker is missing | U49: Yes | V49: =IF(N49="","",IF(Q49="Yes","❌ Disc",IF(P49="No","⚠ Missing",IF(S49="Yes","✓ OK","⚠ Check")))) -> ⚠ Check | W49: 46248 | X49: Sunil CR | Y49: Yes | Z49: No | AA49: Minor defect | AB49: No | AC49: Categorization sticker is missing | AD49: Yes | AE49: =IF(W49="","",IF(Z49="Yes","❌ Disc",IF(Y49="No","⚠ Missing",IF(AB49="Yes","✓ OK","⚠ Check")))) -> ⚠ Check | AF49: 18-09-2026 | AG49: Sunil CR | AH49: Yes | AI49: No | AJ49: Good finish | AK49: Yes | AM49: No | AN49: =IF(AF49="","",IF(AI49="Yes","❌ Disc",IF(AH49="No","⚠ Missing",IF(AK49="Yes","✓ OK","⚠ Check")))) -> ✓ OK | AW49: =IF(AO49="","",IF(AR49="Yes","❌ Disc",IF(AQ49="No","⚠ Missing",IF(AT49="Yes","✓ OK","⚠ Check"))))
A50: 54 | B50: BD-LAM-2024-0002 | C50: Royal Touch - RT Crystal Z+ PP 1166 1.25mm | D50: Royal Touche | E50: 46125 | F50: Sunil CR | G50: No | H50: No | I50: Not Available | J50: No | L50: Yes | M50: =IF(E50="","",IF(H50="Yes","❌ Disc",IF(G50="No","⚠ Missing",IF(J50="Yes","✓ OK","⚠ Check")))) -> ⚠ Missing | N50: 46193 | O50: Sunil CR | P50: No | Q50: No | R50: Not Available | S50: No | U50: Yes | V50: =IF(N50="","",IF(Q50="Yes","❌ Disc",IF(P50="No","⚠ Missing",IF(S50="Yes","✓ OK","⚠ Check")))) -> ⚠ Missing | W50: 46248 | X50: Sunil CR | Y50: No | Z50: No | AA50: Not Available | AB50: No | AD50: Yes | AE50: =IF(W50="","",IF(Z50="Yes","❌ Disc",IF(Y50="No","⚠ Missing",IF(AB50="Yes","✓ OK","⚠ Check")))) -> ⚠ Missing | AF50: 18-09-2026 | AG50: Sunil CR | AH50: No | AI50: No | AJ50: Not Available | AK50: No | AM50: Yes | AN50: =IF(AF50="","",IF(AI50="Yes","❌ Disc",IF(AH50="No","⚠ Missing",IF(AK50="Yes","✓ OK","⚠ Check")))) -> ⚠ Missing | AW50: =IF(AO50="","",IF(AR50="Yes","❌ Disc",IF(AQ50="No","⚠ Missing",IF(AT50="Yes","✓ OK","⚠ Check"))))
A51: 55 | B51: BD-LAM-2023-0002 | C51: Royal Touche - BM - 1746 - 1.25mm(Diamond) | D51: Royal Touche | E51: 46125 | F51: Sunil CR | G51: Yes | H51: No | I51: Good finish | J51: Yes | L51: No | M51: =IF(E51="","",IF(H51="Yes","❌ Disc",IF(G51="No","⚠ Missing",IF(J51="Yes","✓ OK","⚠ Check")))) -> ✓ OK | N51: 46193 | O51: Sunil CR | P51: Yes | Q51: No | R51: Good finish | S51: Yes | U51: No | V51: =IF(N51="","",IF(Q51="Yes","❌ Disc",IF(P51="No","⚠ Missing",IF(S51="Yes","✓ OK","⚠ Check")))) -> ✓ OK | W51: 46248 | X51: Sunil CR | Y51: Yes | Z51: No | AA51: Good finish | AB51: Yes | AD51: No | AE51: =IF(W51="","",IF(Z51="Yes","❌ Disc",IF(Y51="No","⚠ Missing",IF(AB51="Yes","✓ OK","⚠ Check")))) -> ✓ OK | AF51: 18-09-2026 | AG51: Sunil CR | AH51: Yes | AI51: No | AJ51: Good finish | AK51: Yes | AM51: No | AN51: =IF(AF51="","",IF(AI51="Yes","❌ Disc",IF(AH51="No","⚠ Missing",IF(AK51="Yes","✓ OK","⚠ Check")))) -> ✓ OK | AW51: =IF(AO51="","",IF(AR51="Yes","❌ Disc",IF(AQ51="No","⚠ Missing",IF(AT51="Yes","✓ OK","⚠ Check"))))
A52: 56 | B52: BD-LAM-2023-0009 | C52: Royal Touche - CRY - 1164 - 1.25mm(Diamond) | D52: Royal Touche | E52: 46125 | F52: Sunil CR | G52: Yes | H52: No | I52: Minor defect | J52: No | K52: Name Sticker to be Changed | L52: Yes | M52: =IF(E52="","",IF(H52="Yes","❌ Disc",IF(G52="No","⚠ Missing",IF(J52="Yes","✓ OK","⚠ Check")))) -> ⚠ Check | N52: 46193 | O52: Sunil CR | P52: Yes | Q52: No | R52: Minor defect | S52: No | T52: Name Sticker to be Changed | U52: Yes | V52: =IF(N52="","",IF(Q52="Yes","❌ Disc",IF(P52="No","⚠ Missing",IF(S52="Yes","✓ OK","⚠ Check")))) -> ⚠ Check | W52: 46248 | X52: Sunil CR | Y52: Yes | Z52: No | AA52: Good finish | AB52: Yes | AD52: Yes | AE52: =IF(W52="","",IF(Z52="Yes","❌ Disc",IF(Y52="No","⚠ Missing",IF(AB52="Yes","✓ OK","⚠ Check")))) -> ✓ OK | AF52: 18-09-2026 | AG52: Sunil CR | AH52: Yes | AI52: No | AJ52: Good finish | AK52: Yes | AM52: No | AN52: =IF(AF52="","",IF(AI52="Yes","❌ Disc",IF(AH52="No","⚠ Missing",IF(AK52="Yes","✓ OK","⚠ Check")))) -> ✓ OK | AW52: =IF(AO52="","",IF(AR52="Yes","❌ Disc",IF(AQ52="No","⚠ Missing",IF(AT52="Yes","✓ OK","⚠ Check"))))
A53: 57 | B53: BD-LAM-2023-0008 | C53: Royal Touche - CRY - 1174 - 1.25mm(Diamond) | D53: Royal Touche | E53: 46125 | F53: Sunil CR | G53: Yes | H53: No | I53: Good finish | J53: Yes | L53: No | M53: =IF(E53="","",IF(H53="Yes","❌ Disc",IF(G53="No","⚠ Missing",IF(J53="Yes","✓ OK","⚠ Check")))) -> ✓ OK | N53: 46193 | O53: Sunil CR | P53: Yes | Q53: No | R53: Good finish | S53: Yes | U53: No | V53: =IF(N53="","",IF(Q53="Yes","❌ Disc",IF(P53="No","⚠ Missing",IF(S53="Yes","✓ OK","⚠ Check")))) -> ✓ OK | W53: 46248 | X53: Sunil CR | Y53: Yes | Z53: No | AA53: Good finish | AB53: Yes | AD53: No | AE53: =IF(W53="","",IF(Z53="Yes","❌ Disc",IF(Y53="No","⚠ Missing",IF(AB53="Yes","✓ OK","⚠ Check")))) -> ✓ OK | AF53: 18-09-2026 | AG53: Sunil CR | AH53: Yes | AI53: No | AJ53: Good finish | AK53: Yes | AM53: No | AN53: =IF(AF53="","",IF(AI53="Yes","❌ Disc",IF(AH53="No","⚠ Missing",IF(AK53="Yes","✓ OK","⚠ Check")))) -> ✓ OK | AW53: =IF(AO53="","",IF(AR53="Yes","❌ Disc",IF(AQ53="No","⚠ Missing",IF(AT53="Yes","✓ OK","⚠ Check"))))
A54: 58 | B54: BD-LAM-2023-0017 | C54: Royal Touche - Crystal - 1104 - 1.25mm(Diamond) | D54: Royal Touche | E54: 46125 | F54: Sunil CR | G54: Yes | H54: No | I54: Good finish | J54: Yes | L54: No | M54: =IF(E54="","",IF(H54="Yes","❌ Disc",IF(G54="No","⚠ Missing",IF(J54="Yes","✓ OK","⚠ Check")))) -> ✓ OK | N54: 46193 | O54: Sunil CR | P54: Yes | Q54: No | R54: Good finish | S54: Yes | U54: No | V54: =IF(N54="","",IF(Q54="Yes","❌ Disc",IF(P54="No","⚠ Missing",IF(S54="Yes","✓ OK","⚠ Check")))) -> ✓ OK | W54: 46248 | X54: Sunil CR | Y54: Yes | Z54: No | AA54: Good finish | AB54: Yes | AD54: No | AE54: =IF(W54="","",IF(Z54="Yes","❌ Disc",IF(Y54="No","⚠ Missing",IF(AB54="Yes","✓ OK","⚠ Check")))) -> ✓ OK | AF54: 18-09-2026 | AG54: Sunil CR | AH54: Yes | AI54: No | AJ54: Good finish | AK54: Yes | AM54: No | AN54: =IF(AF54="","",IF(AI54="Yes","❌ Disc",IF(AH54="No","⚠ Missing",IF(AK54="Yes","✓ OK","⚠ Check")))) -> ✓ OK | AW54: =IF(AO54="","",IF(AR54="Yes","❌ Disc",IF(AQ54="No","⚠ Missing",IF(AT54="Yes","✓ OK","⚠ Check"))))
A55: 59 | B55: BD-LAM-2023-0016 | C55: Royal Touche - Crystal - 1105 - 1.25mm(Diamond) | D55: Royal Touche | E55: 46125 | F55: Sunil CR | G55: Yes | H55: No | I55: Good finish | J55: Yes | L55: No | M55: =IF(E55="","",IF(H55="Yes","❌ Disc",IF(G55="No","⚠ Missing",IF(J55="Yes","✓ OK","⚠ Check")))) -> ✓ OK | N55: 46193 | O55: Sunil CR | P55: Yes | Q55: No | R55: Good finish | S55: Yes | U55: No | V55: =IF(N55="","",IF(Q55="Yes","❌ Disc",IF(P55="No","⚠ Missing",IF(S55="Yes","✓ OK","⚠ Check")))) -> ✓ OK | W55: 46248 | X55: Sunil CR | Y55: Yes | Z55: No | AA55: Good finish | AB55: Yes | AD55: No | AE55: =IF(W55="","",IF(Z55="Yes","❌ Disc",IF(Y55="No","⚠ Missing",IF(AB55="Yes","✓ OK","⚠ Check")))) -> ✓ OK | AF55: 18-09-2026 | AG55: Sunil CR | AH55: Yes | AI55: No | AJ55: Good finish | AK55: Yes | AM55: No | AN55: =IF(AF55="","",IF(AI55="Yes","❌ Disc",IF(AH55="No","⚠ Missing",IF(AK55="Yes","✓ OK","⚠ Check")))) -> ✓ OK | AW55: =IF(AO55="","",IF(AR55="Yes","❌ Disc",IF(AQ55="No","⚠ Missing",IF(AT55="Yes","✓ OK","⚠ Check"))))
A56: 60 | B56: BD-LAM-2023-0023 | C56: Royal Touche - Crystal - 1244 - 1.25mm(Diamond) | D56: Royal Touche | E56: 46125 | F56: Sunil CR | G56: Yes | H56: No | I56: Good finish | J56: Yes | L56: No | M56: =IF(E56="","",IF(H56="Yes","❌ Disc",IF(G56="No","⚠ Missing",IF(J56="Yes","✓ OK","⚠ Check")))) -> ✓ OK | N56: 46193 | O56: Sunil CR | P56: Yes | Q56: No | R56: Good finish | S56: Yes | U56: No | V56: =IF(N56="","",IF(Q56="Yes","❌ Disc",IF(P56="No","⚠ Missing",IF(S56="Yes","✓ OK","⚠ Check")))) -> ✓ OK | W56: 46248 | X56: Sunil CR | Y56: Yes | Z56: No | AA56: Good finish | AB56: Yes | AD56: No | AE56: =IF(W56="","",IF(Z56="Yes","❌ Disc",IF(Y56="No","⚠ Missing",IF(AB56="Yes","✓ OK","⚠ Check")))) -> ✓ OK | AF56: 18-09-2026 | AG56: Sunil CR | AH56: Yes | AI56: No | AJ56: Good finish | AK56: Yes | AM56: No | AN56: =IF(AF56="","",IF(AI56="Yes","❌ Disc",IF(AH56="No","⚠ Missing",IF(AK56="Yes","✓ OK","⚠ Check")))) -> ✓ OK | AW56: =IF(AO56="","",IF(AR56="Yes","❌ Disc",IF(AQ56="No","⚠ Missing",IF(AT56="Yes","✓ OK","⚠ Check"))))
A57: 61 | B57: BD-LAM-2023-0022 | C57: Royal Touche - Crystal - Z+BG - 1214 - 1.25mm(Diamond) | D57: Royal Touche | E57: 46125 | F57: Sunil CR | G57: Yes | H57: No | I57: Good finish | J57: Yes | L57: No | M57: =IF(E57="","",IF(H57="Yes","❌ Disc",IF(G57="No","⚠ Missing",IF(J57="Yes","✓ OK","⚠ Check")))) -> ✓ OK | N57: 46193 | O57: Sunil CR | P57: Yes | Q57: No | R57: Good finish | S57: Yes | U57: No | V57: =IF(N57="","",IF(Q57="Yes","❌ Disc",IF(P57="No","⚠ Missing",IF(S57="Yes","✓ OK","⚠ Check")))) -> ✓ OK | W57: 46248 | X57: Sunil CR | Y57: Yes | Z57: No | AA57: Good finish | AB57: Yes | AD57: No | AE57: =IF(W57="","",IF(Z57="Yes","❌ Disc",IF(Y57="No","⚠ Missing",IF(AB57="Yes","✓ OK","⚠ Check")))) -> ✓ OK | AF57: 18-09-2026 | AG57: Sunil CR | AH57: Yes | AI57: No | AJ57: Good finish | AK57: Yes | AM57: No | AN57: =IF(AF57="","",IF(AI57="Yes","❌ Disc",IF(AH57="No","⚠ Missing",IF(AK57="Yes","✓ OK","⚠ Check")))) -> ✓ OK | AW57: =IF(AO57="","",IF(AR57="Yes","❌ Disc",IF(AQ57="No","⚠ Missing",IF(AT57="Yes","✓ OK","⚠ Check"))))
A58: 62 | B58: BD-LAM-2023-0025 | C58: Royal Touche - Crystal Matty+ - 1249 - 1.25mm(Diamond) | D58: Royal Touche | E58: 46125 | F58: Sunil CR | G58: Yes | H58: No | I58: Good finish | J58: Yes | L58: No | M58: =IF(E58="","",IF(H58="Yes","❌ Disc",IF(G58="No","⚠ Missing",IF(J58="Yes","✓ OK","⚠ Check")))) -> ✓ OK | N58: 46193 | O58: Sunil CR | P58: Yes | Q58: No | R58: Good finish | S58: Yes | U58: No | V58: =IF(N58="","",IF(Q58="Yes","❌ Disc",IF(P58="No","⚠ Missing",IF(S58="Yes","✓ OK","⚠ Check")))) -> ✓ OK | W58: 46248 | X58: Sunil CR | Y58: Yes | Z58: No | AA58: Good finish | AB58: Yes | AD58: No | AE58: =IF(W58="","",IF(Z58="Yes","❌ Disc",IF(Y58="No","⚠ Missing",IF(AB58="Yes","✓ OK","⚠ Check")))) -> ✓ OK | AF58: 18-09-2026 | AG58: Sunil CR | AH58: Yes | AI58: No | AJ58: Good finish | AK58: Yes | AM58: No | AN58: =IF(AF58="","",IF(AI58="Yes","❌ Disc",IF(AH58="No","⚠ Missing",IF(AK58="Yes","✓ OK","⚠ Check")))) -> ✓ OK | AW58: =IF(AO58="","",IF(AR58="Yes","❌ Disc",IF(AQ58="No","⚠ Missing",IF(AT58="Yes","✓ OK","⚠ Check"))))
A59: 63 | B59: BD-LAM-2023-0037 | C59: Royal Touche - DL - 1112 - 1.25mm(Diamond) | D59: Royal Touche | E59: 46125 | F59: Sunil CR | G59: Yes | H59: No | I59: Good finish | J59: Yes | L59: No | M59: =IF(E59="","",IF(H59="Yes","❌ Disc",IF(G59="No","⚠ Missing",IF(J59="Yes","✓ OK","⚠ Check")))) -> ✓ OK | N59: 46193 | O59: Sunil CR | P59: Yes | Q59: No | R59: Good finish | S59: Yes | U59: No | V59: =IF(N59="","",IF(Q59="Yes","❌ Disc",IF(P59="No","⚠ Missing",IF(S59="Yes","✓ OK","⚠ Check")))) -> ✓ OK | W59: 46248 | X59: Sunil CR | Y59: Yes | Z59: No | AA59: Good finish | AB59: Yes | AD59: No | AE59: =IF(W59="","",IF(Z59="Yes","❌ Disc",IF(Y59="No","⚠ Missing",IF(AB59="Yes","✓ OK","⚠ Check")))) -> ✓ OK | AF59: 18-09-2026 | AG59: Sunil CR | AH59: No | AI59: Yes | AJ59: Discontinued | AK59: No | AM59: No | AN59: =IF(AF59="","",IF(AI59="Yes","❌ Disc",IF(AH59="No","⚠ Missing",IF(AK59="Yes","✓ OK","⚠ Check")))) -> ❌ Disc | AW59: =IF(AO59="","",IF(AR59="Yes","❌ Disc",IF(AQ59="No","⚠ Missing",IF(AT59="Yes","✓ OK","⚠ Check"))))
A60: 64 | B60: BD-LAM-2023-0030 | C60: Royal Touche - OC - 1691 - 1.25mm(Diamond) | D60: Royal Touche | E60: 46125 | F60: Sunil CR | G60: Yes | H60: No | I60: Good finish | J60: Yes | L60: No | M60: =IF(E60="","",IF(H60="Yes","❌ Disc",IF(G60="No","⚠ Missing",IF(J60="Yes","✓ OK","⚠ Check")))) -> ✓ OK | N60: 46193 | O60: Sunil CR | P60: Yes | Q60: No | R60: Good finish | S60: Yes | U60: No | V60: =IF(N60="","",IF(Q60="Yes","❌ Disc",IF(P60="No","⚠ Missing",IF(S60="Yes","✓ OK","⚠ Check")))) -> ✓ OK | W60: 46248 | X60: Sunil CR | Y60: Yes | Z60: No | AA60: Good finish | AB60: Yes | AD60: No | AE60: =IF(W60="","",IF(Z60="Yes","❌ Disc",IF(Y60="No","⚠ Missing",IF(AB60="Yes","✓ OK","⚠ Check")))) -> ✓ OK | AF60: 18-09-2026 | AG60: Sunil CR | AH60: Yes | AI60: No | AJ60: Good finish | AK60: Yes | AM60: No | AN60: =IF(AF60="","",IF(AI60="Yes","❌ Disc",IF(AH60="No","⚠ Missing",IF(AK60="Yes","✓ OK","⚠ Check")))) -> ✓ OK | AW60: =IF(AO60="","",IF(AR60="Yes","❌ Disc",IF(AQ60="No","⚠ Missing",IF(AT60="Yes","✓ OK","⚠ Check"))))
A61: 65 | B61: BD-LAM-2023-0031 | C61: Royal Touche - OC - 1692 - 1.25mm(Diamond) | D61: Royal Touche | E61: 46125 | F61: Sunil CR | G61: Yes | H61: No | I61: Good finish | J61: Yes | L61: No | M61: =IF(E61="","",IF(H61="Yes","❌ Disc",IF(G61="No","⚠ Missing",IF(J61="Yes","✓ OK","⚠ Check")))) -> ✓ OK | N61: 46193 | O61: Sunil CR | P61: Yes | Q61: No | R61: Good finish | S61: Yes | U61: No | V61: =IF(N61="","",IF(Q61="Yes","❌ Disc",IF(P61="No","⚠ Missing",IF(S61="Yes","✓ OK","⚠ Check")))) -> ✓ OK | W61: 46248 | X61: Sunil CR | Y61: Yes | Z61: No | AA61: Good finish | AB61: Yes | AD61: No | AE61: =IF(W61="","",IF(Z61="Yes","❌ Disc",IF(Y61="No","⚠ Missing",IF(AB61="Yes","✓ OK","⚠ Check")))) -> ✓ OK | AF61: 18-09-2026 | AG61: Sunil CR | AH61: Yes | AI61: No | AJ61: Good finish | AK61: Yes | AM61: No | AN61: =IF(AF61="","",IF(AI61="Yes","❌ Disc",IF(AH61="No","⚠ Missing",IF(AK61="Yes","✓ OK","⚠ Check")))) -> ✓ OK | AW61: =IF(AO61="","",IF(AR61="Yes","❌ Disc",IF(AQ61="No","⚠ Missing",IF(AT61="Yes","✓ OK","⚠ Check"))))
A62: 66 | B62: BD-LAM-2023-0006 | C62: Royal Touche - PU - 1628 - 1.25mm(Diamond) | D62: Royal Touche | E62: 46125 | F62: Sunil CR | G62: Yes | H62: No | I62: Good finish | J62: Yes | L62: No | M62: =IF(E62="","",IF(H62="Yes","❌ Disc",IF(G62="No","⚠ Missing",IF(J62="Yes","✓ OK","⚠ Check")))) -> ✓ OK | N62: 46193 | O62: Sunil CR | P62: Yes | Q62: No | R62: Good finish | S62: Yes | U62: No | V62: =IF(N62="","",IF(Q62="Yes","❌ Disc",IF(P62="No","⚠ Missing",IF(S62="Yes","✓ OK","⚠ Check")))) -> ✓ OK | W62: 46248 | X62: Sunil CR | Y62: Yes | Z62: No | AA62: Good finish | AB62: Yes | AD62: No | AE62: =IF(W62="","",IF(Z62="Yes","❌ Disc",IF(Y62="No","⚠ Missing",IF(AB62="Yes","✓ OK","⚠ Check")))) -> ✓ OK | AF62: 18-09-2026 | AG62: Sunil CR | AH62: Yes | AI62: No | AJ62: Good finish | AK62: Yes | AM62: No | AN62: =IF(AF62="","",IF(AI62="Yes","❌ Disc",IF(AH62="No","⚠ Missing",IF(AK62="Yes","✓ OK","⚠ Check")))) -> ✓ OK | AW62: =IF(AO62="","",IF(AR62="Yes","❌ Disc",IF(AQ62="No","⚠ Missing",IF(AT62="Yes","✓ OK","⚠ Check"))))
A63: 67 | B63: BD-LAM-2023-0007 | C63: Royal Touche - PU - 1721 - 1.25mm(Diamond) | D63: Royal Touche | E63: 46125 | F63: Sunil CR | G63: Yes | H63: No | I63: Good finish | J63: Yes | L63: No | M63: =IF(E63="","",IF(H63="Yes","❌ Disc",IF(G63="No","⚠ Missing",IF(J63="Yes","✓ OK","⚠ Check")))) -> ✓ OK | N63: 46193 | O63: Sunil CR | P63: Yes | Q63: No | R63: Good finish | S63: Yes | U63: No | V63: =IF(N63="","",IF(Q63="Yes","❌ Disc",IF(P63="No","⚠ Missing",IF(S63="Yes","✓ OK","⚠ Check")))) -> ✓ OK | W63: 46248 | X63: Sunil CR | Y63: Yes | Z63: No | AA63: Good finish | AB63: Yes | AD63: No | AE63: =IF(W63="","",IF(Z63="Yes","❌ Disc",IF(Y63="No","⚠ Missing",IF(AB63="Yes","✓ OK","⚠ Check")))) -> ✓ OK | AF63: 18-09-2026 | AG63: Sunil CR | AH63: Yes | AI63: No | AJ63: Good finish | AK63: Yes | AM63: No | AN63: =IF(AF63="","",IF(AI63="Yes","❌ Disc",IF(AH63="No","⚠ Missing",IF(AK63="Yes","✓ OK","⚠ Check")))) -> ✓ OK | AW63: =IF(AO63="","",IF(AR63="Yes","❌ Disc",IF(AQ63="No","⚠ Missing",IF(AT63="Yes","✓ OK","⚠ Check"))))
A64: 68 | B64: BD-LAM-2024-0001 | C64: Royal Touche - RT Crystal Z+ PP 1129 1.25mm(Diamond) | D64: Royal Touche | E64: 46125 | F64: Sunil CR | G64: Yes | H64: No | I64: Minor defect | J64: No | K64: Categorization sticker is missing | L64: Yes | M64: =IF(E64="","",IF(H64="Yes","❌ Disc",IF(G64="No","⚠ Missing",IF(J64="Yes","✓ OK","⚠ Check")))) -> ⚠ Check | N64: 46193 | O64: Sunil CR | P64: Yes | Q64: No | R64: Minor defect | S64: No | T64: Categorization sticker is missing | U64: Yes | V64: =IF(N64="","",IF(Q64="Yes","❌ Disc",IF(P64="No","⚠ Missing",IF(S64="Yes","✓ OK","⚠ Check")))) -> ⚠ Check | W64: 46248 | X64: Sunil CR | Y64: Yes | Z64: No | AA64: Minor defect | AB64: No | AC64: Categorization sticker is missing | AD64: Yes | AE64: =IF(W64="","",IF(Z64="Yes","❌ Disc",IF(Y64="No","⚠ Missing",IF(AB64="Yes","✓ OK","⚠ Check")))) -> ⚠ Check | AF64: 18-09-2026 | AG64: Sunil CR | AH64: Yes | AI64: No | AJ64: Good finish | AK64: Yes | AM64: No | AN64: =IF(AF64="","",IF(AI64="Yes","❌ Disc",IF(AH64="No","⚠ Missing",IF(AK64="Yes","✓ OK","⚠ Check")))) -> ✓ OK | AW64: =IF(AO64="","",IF(AR64="Yes","❌ Disc",IF(AQ64="No","⚠ Missing",IF(AT64="Yes","✓ OK","⚠ Check"))))
A65: 69 | B65: BD-LAM-2024-0097 | C65: LAM SL AC 1mm 2383 Ktami Oreo Elm(Gold) | D65: Stylam | E65: 46125 | F65: Sunil CR | G65: Yes | H65: No | I65: Good finish | J65: Yes | L65: No | M65: =IF(E65="","",IF(H65="Yes","❌ Disc",IF(G65="No","⚠ Missing",IF(J65="Yes","✓ OK","⚠ Check")))) -> ✓ OK | N65: 46193 | O65: Sunil CR | P65: Yes | Q65: No | R65: Good finish | S65: Yes | U65: No | V65: =IF(N65="","",IF(Q65="Yes","❌ Disc",IF(P65="No","⚠ Missing",IF(S65="Yes","✓ OK","⚠ Check")))) -> ✓ OK | W65: 46248 | X65: Sunil CR | Y65: No | Z65: Yes | AA65: Discontinued | AB65: No | AD65: No | AE65: =IF(W65="","",IF(Z65="Yes","❌ Disc",IF(Y65="No","⚠ Missing",IF(AB65="Yes","✓ OK","⚠ Check")))) -> ❌ Disc | AF65: 18-09-2026 | AG65: Sunil CR | AH65: No | AI65: Yes | AJ65: Discontinued | AK65: No | AM65: No | AN65: =IF(AF65="","",IF(AI65="Yes","❌ Disc",IF(AH65="No","⚠ Missing",IF(AK65="Yes","✓ OK","⚠ Check")))) -> ❌ Disc | AW65: =IF(AO65="","",IF(AR65="Yes","❌ Disc",IF(AQ65="No","⚠ Missing",IF(AT65="Yes","✓ OK","⚠ Check"))))
A66: 70 | B66: BD-LAM-2024-0079 | C66: Lam SL AC 1mm 2905 Amalfi Tan Oak(Gold) | D66: Stylam | E66: 46125 | F66: Sunil CR | G66: Yes | H66: No | I66: Good finish | J66: Yes | L66: No | M66: =IF(E66="","",IF(H66="Yes","❌ Disc",IF(G66="No","⚠ Missing",IF(J66="Yes","✓ OK","⚠ Check")))) -> ✓ OK | N66: 46193 | O66: Sunil CR | P66: Yes | Q66: No | R66: Good finish | S66: Yes | U66: No | V66: =IF(N66="","",IF(Q66="Yes","❌ Disc",IF(P66="No","⚠ Missing",IF(S66="Yes","✓ OK","⚠ Check")))) -> ✓ OK | W66: 46248 | X66: Sunil CR | Y66: Yes | Z66: No | AA66: Good finish | AB66: Yes | AD66: No | AE66: =IF(W66="","",IF(Z66="Yes","❌ Disc",IF(Y66="No","⚠ Missing",IF(AB66="Yes","✓ OK","⚠ Check")))) -> ✓ OK | AF66: 18-09-2026 | AG66: Sunil CR | AH66: No | AI66: Yes | AJ66: Discontinued | AK66: No | AM66: No | AN66: =IF(AF66="","",IF(AI66="Yes","❌ Disc",IF(AH66="No","⚠ Missing",IF(AK66="Yes","✓ OK","⚠ Check")))) -> ❌ Disc | AW66: =IF(AO66="","",IF(AR66="Yes","❌ Disc",IF(AQ66="No","⚠ Missing",IF(AT66="Yes","✓ OK","⚠ Check"))))
A67: 71 | B67: BD-LAM-2023-0144 | C67: Lam SL AFP 1mm 1005 Creamy White(Diamond) | D67: Stylam | E67: 46125 | F67: Sunil CR | G67: Yes | H67: No | I67: Good finish | J67: Yes | L67: No | M67: =IF(E67="","",IF(H67="Yes","❌ Disc",IF(G67="No","⚠ Missing",IF(J67="Yes","✓ OK","⚠ Check")))) -> ✓ OK | N67: 46193 | O67: Sunil CR | P67: Yes | Q67: No | R67: Good finish | S67: Yes | U67: No | V67: =IF(N67="","",IF(Q67="Yes","❌ Disc",IF(P67="No","⚠ Missing",IF(S67="Yes","✓ OK","⚠ Check")))) -> ✓ OK | W67: 46248 | X67: Sunil CR | Y67: Yes | Z67: No | AA67: Good finish | AB67: Yes | AD67: No | AE67: =IF(W67="","",IF(Z67="Yes","❌ Disc",IF(Y67="No","⚠ Missing",IF(AB67="Yes","✓ OK","⚠ Check")))) -> ✓ OK | AF67: 18-09-2026 | AG67: Sunil CR | AH67: No | AI67: Yes | AJ67: Discontinued | AK67: No | AM67: No | AN67: =IF(AF67="","",IF(AI67="Yes","❌ Disc",IF(AH67="No","⚠ Missing",IF(AK67="Yes","✓ OK","⚠ Check")))) -> ❌ Disc | AW67: =IF(AO67="","",IF(AR67="Yes","❌ Disc",IF(AQ67="No","⚠ Missing",IF(AT67="Yes","✓ OK","⚠ Check"))))
A68: 72 | B68: BD-LAM-2024-0054 | C68: Lam SL AFP 1mm 1014 City Shadow(Diamond) | D68: Stylam | E68: 46125 | F68: Sunil CR | G68: Yes | H68: No | I68: Good finish | J68: Yes | L68: No | M68: =IF(E68="","",IF(H68="Yes","❌ Disc",IF(G68="No","⚠ Missing",IF(J68="Yes","✓ OK","⚠ Check")))) -> ✓ OK | N68: 46193 | O68: Sunil CR | P68: Yes | Q68: No | R68: Good finish | S68: Yes | U68: No | V68: =IF(N68="","",IF(Q68="Yes","❌ Disc",IF(P68="No","⚠ Missing",IF(S68="Yes","✓ OK","⚠ Check")))) -> ✓ OK | W68: 46248 | X68: Sunil CR | Y68: Yes | Z68: No | AA68: Good finish | AB68: Yes | AD68: No | AE68: =IF(W68="","",IF(Z68="Yes","❌ Disc",IF(Y68="No","⚠ Missing",IF(AB68="Yes","✓ OK","⚠ Check")))) -> ✓ OK | AF68: 18-09-2026 | AG68: Sunil CR | AH68: Yes | AI68: No | AJ68: Good finish | AK68: Yes | AM68: No | AN68: =IF(AF68="","",IF(AI68="Yes","❌ Disc",IF(AH68="No","⚠ Missing",IF(AK68="Yes","✓ OK","⚠ Check")))) -> ✓ OK | AW68: =IF(AO68="","",IF(AR68="Yes","❌ Disc",IF(AQ68="No","⚠ Missing",IF(AT68="Yes","✓ OK","⚠ Check"))))
A69: 73 | B69: BD-LAM-2023-0188 | C69: Lam SL AFP 1mm 1017 Jaisalmer Brown(Diamond) | D69: Stylam | E69: 46125 | F69: Sunil CR | G69: Yes | H69: No | I69: Good finish | J69: Yes | L69: No | M69: =IF(E69="","",IF(H69="Yes","❌ Disc",IF(G69="No","⚠ Missing",IF(J69="Yes","✓ OK","⚠ Check")))) -> ✓ OK | N69: 46193 | O69: Sunil CR | P69: Yes | Q69: No | R69: Good finish | S69: Yes | U69: No | V69: =IF(N69="","",IF(Q69="Yes","❌ Disc",IF(P69="No","⚠ Missing",IF(S69="Yes","✓ OK","⚠ Check")))) -> ✓ OK | W69: 46248 | X69: Sunil CR | Y69: Yes | Z69: No | AA69: Good finish | AB69: Yes | AD69: No | AE69: =IF(W69="","",IF(Z69="Yes","❌ Disc",IF(Y69="No","⚠ Missing",IF(AB69="Yes","✓ OK","⚠ Check")))) -> ✓ OK | AF69: 18-09-2026 | AG69: Sunil CR | AH69: Yes | AI69: No | AJ69: Good finish | AK69: Yes | AM69: No | AN69: =IF(AF69="","",IF(AI69="Yes","❌ Disc",IF(AH69="No","⚠ Missing",IF(AK69="Yes","✓ OK","⚠ Check")))) -> ✓ OK | AW69: =IF(AO69="","",IF(AR69="Yes","❌ Disc",IF(AQ69="No","⚠ Missing",IF(AT69="Yes","✓ OK","⚠ Check"))))
A70: 74 | B70: BD-LAM-2023-0226 | C70: Lam SL AFP 1mm 1020 Off White(Diamond) | D70: Stylam | E70: 46125 | F70: Sunil CR | G70: Yes | H70: No | I70: Minor defect | J70: No | K70: Name Sticker to be Changed | L70: Yes | M70: =IF(E70="","",IF(H70="Yes","❌ Disc",IF(G70="No","⚠ Missing",IF(J70="Yes","✓ OK","⚠ Check")))) -> ⚠ Check | N70: 46193 | O70: Sunil CR | P70: Yes | Q70: No | R70: Minor defect | S70: No | T70: Name Sticker to be Changed | U70: Yes | V70: =IF(N70="","",IF(Q70="Yes","❌ Disc",IF(P70="No","⚠ Missing",IF(S70="Yes","✓ OK","⚠ Check")))) -> ⚠ Check | W70: 46248 | X70: Sunil CR | Y70: Yes | Z70: No | AA70: Good finish | AB70: Yes | AD70: Yes | AE70: =IF(W70="","",IF(Z70="Yes","❌ Disc",IF(Y70="No","⚠ Missing",IF(AB70="Yes","✓ OK","⚠ Check")))) -> ✓ OK | AF70: 18-09-2026 | AG70: Sunil CR | AH70: Yes | AI70: Yes | AJ70: Good finish | AK70: Yes | AM70: No | AN70: =IF(AF70="","",IF(AI70="Yes","❌ Disc",IF(AH70="No","⚠ Missing",IF(AK70="Yes","✓ OK","⚠ Check")))) -> ❌ Disc | AW70: =IF(AO70="","",IF(AR70="Yes","❌ Disc",IF(AQ70="No","⚠ Missing",IF(AT70="Yes","✓ OK","⚠ Check"))))
A71: 75 | B71: BD-LAM-2023-0275 | C71: Lam SL AFP 1mm 1037 Soldier Green (Diamond) | D71: Stylam | E71: 46125 | F71: Sunil CR | G71: Yes | H71: No | I71: Good finish | J71: Yes | L71: No | M71: =IF(E71="","",IF(H71="Yes","❌ Disc",IF(G71="No","⚠ Missing",IF(J71="Yes","✓ OK","⚠ Check")))) -> ✓ OK | N71: 46193 | O71: Sunil CR | P71: Yes | Q71: No | R71: Good finish | S71: Yes | U71: No | V71: =IF(N71="","",IF(Q71="Yes","❌ Disc",IF(P71="No","⚠ Missing",IF(S71="Yes","✓ OK","⚠ Check")))) -> ✓ OK | W71: 46248 | X71: Sunil CR | Y71: Yes | Z71: No | AA71: Good finish | AB71: Yes | AD71: No | AE71: =IF(W71="","",IF(Z71="Yes","❌ Disc",IF(Y71="No","⚠ Missing",IF(AB71="Yes","✓ OK","⚠ Check")))) -> ✓ OK | AF71: 18-09-2026 | AG71: Sunil CR | AH71: Yes | AI71: No | AJ71: Good finish | AK71: Yes | AM71: No | AN71: =IF(AF71="","",IF(AI71="Yes","❌ Disc",IF(AH71="No","⚠ Missing",IF(AK71="Yes","✓ OK","⚠ Check")))) -> ✓ OK | AW71: =IF(AO71="","",IF(AR71="Yes","❌ Disc",IF(AQ71="No","⚠ Missing",IF(AT71="Yes","✓ OK","⚠ Check"))))
...

Sheet Acrylic n Crystal Acrylic
A1: 📋 HRBR EC — ACRYLIC N CRYSTAL ACRYLIC | Multi-Round Audit Tracker
A2: ➤ Fill AUDIT DATE & AUDITOR first in each block | Yellow = Comments | Status auto-updates | Next audit → use next block
E3: AUDIT 1 | N3: AUDIT 2 | W3: AUDIT 3 | AF3: AUDIT 4 | AO3: AUDIT 5
A4: # | B4: ERP Code | C4: Material / Studio Name | D4: Brand | E4: Audit Date | F4: Auditor | G4: Sample in EC? | H4: Discontinued by Vendor? | I4: Visual Condition | J4: Conformance (Yes/No) | K4: COMMENTS / REMARKS | L4: Follow-Up Action | M4: Status | N4: Audit Date | O4: Auditor | P4: Sample in EC? | Q4: Discontinued by Vendor? | R4: Visual Condition | S4: Conformance (Yes/No) | T4: COMMENTS / REMARKS | U4: Follow-Up Action | V4: Status | W4: Audit Date | X4: Auditor | Y4: Sample in EC? | Z4: Discontinued by Vendor? | AA4: Visual Condition | AB4: Conformance (Yes/No) | AC4: COMMENTS / REMARKS | AD4: Follow-Up Action | AE4: Status | AF4: Audit Date | AG4: Auditor | AH4: Sample in EC? | AI4: Discontinued by Vendor? | AJ4: Visual Condition | AK4: Conformance (Yes/No) | AL4: COMMENTS / REMARKS | AM4: Follow-Up Action | AN4: Status | AO4: Audit Date | AP4: Auditor | AQ4: Sample in EC? | AR4: Discontinued by Vendor? | AS4: Visual Condition | AT4: Conformance (Yes/No) | AU4: COMMENTS / REMARKS | AV4: Follow-Up Action | AW4: Status
A5: 1 | B5: BD-ACR-2025-0020 | C5: Rehau - Acrylic - Biscotti Gloss - 5008P | D5: Rehau | E5: 46125 | F5: Sunil CR | G5: Yes | H5: No | I5: Good finish | J5: Yes | L5: No | M5: =IF(E5="","",IF(H5="Yes","❌ Disc",IF(G5="No","⚠ Missing",IF(J5="Yes","✓ OK","⚠ Check")))) -> ✓ OK | N5: 46193 | O5: Sunil CR | P5: Yes | Q5: No | R5: Good finish | S5: Yes | U5: No | V5: =IF(N5="","",IF(Q5="Yes","❌ Disc",IF(P5="No","⚠ Missing",IF(S5="Yes","✓ OK","⚠ Check")))) -> ✓ OK | W5: 46248 | X5: Sunil CR | Y5: Yes | Z5: No | AA5: Good finish | AB5: Yes | AD5: No | AE5: =IF(W5="","",IF(Z5="Yes","❌ Disc",IF(Y5="No","⚠ Missing",IF(AB5="Yes","✓ OK","⚠ Check")))) -> ✓ OK | AF5: 18-09-2026 | AG5: Sunil CR | AH5: Yes | AI5: No | AJ5: Good finish | AK5: Yes | AM5: No | AN5: =IF(AF5="","",IF(AI5="Yes","❌ Disc",IF(AH5="No","⚠ Missing",IF(AK5="Yes","✓ OK","⚠ Check")))) -> ✓ OK | AW5: =IF(AO5="","",IF(AR5="Yes","❌ Disc",IF(AQ5="No","⚠ Missing",IF(AT5="Yes","✓ OK","⚠ Check"))))
A6: 2 | B6: BD-ACR-2025-0010 | C6: Rehau - Acrylic - Blue Spirulina Gloss - 5015P | D6: Rehau | E6: 46125 | F6: Sunil CR | G6: Yes | H6: No | I6: Good finish | J6: Yes | L6: No | M6: =IF(E6="","",IF(H6="Yes","❌ Disc",IF(G6="No","⚠ Missing",IF(J6="Yes","✓ OK","⚠ Check")))) -> ✓ OK | N6: 46193 | O6: Sunil CR | P6: Yes | Q6: No | R6: Good finish | S6: Yes | U6: No | V6: =IF(N6="","",IF(Q6="Yes","❌ Disc",IF(P6="No","⚠ Missing",IF(S6="Yes","✓ OK","⚠ Check")))) -> ✓ OK | W6: 46248 | X6: Sunil CR | Y6: Yes | Z6: No | AA6: Good finish | AB6: Yes | AD6: No | AE6: =IF(W6="","",IF(Z6="Yes","❌ Disc",IF(Y6="No","⚠ Missing",IF(AB6="Yes","✓ OK","⚠ Check")))) -> ✓ OK | AF6: 18-09-2026 | AG6: Sunil CR | AH6: Yes | AI6: No | AJ6: Good finish | AK6: Yes | AM6: No | AN6: =IF(AF6="","",IF(AI6="Yes","❌ Disc",IF(AH6="No","⚠ Missing",IF(AK6="Yes","✓ OK","⚠ Check")))) -> ✓ OK | AW6: =IF(AO6="","",IF(AR6="Yes","❌ Disc",IF(AQ6="No","⚠ Missing",IF(AT6="Yes","✓ OK","⚠ Check"))))
A7: 3 | B7: BD-ACR-2025-0011 | C7: Rehau - Acrylic - Blue Spirulina Matt - 2015N | D7: Rehau | E7: 46125 | F7: Sunil CR | G7: Yes | H7: No | I7: Good finish | J7: Yes | L7: No | M7: =IF(E7="","",IF(H7="Yes","❌ Disc",IF(G7="No","⚠ Missing",IF(J7="Yes","✓ OK","⚠ Check")))) -> ✓ OK | N7: 46193 | O7: Sunil CR | P7: Yes | Q7: No | R7: Good finish | S7: Yes | U7: No | V7: =IF(N7="","",IF(Q7="Yes","❌ Disc",IF(P7="No","⚠ Missing",IF(S7="Yes","✓ OK","⚠ Check")))) -> ✓ OK | W7: 46248 | X7: Sunil CR | Y7: Yes | Z7: No | AA7: Good finish | AB7: Yes | AD7: No | AE7: =IF(W7="","",IF(Z7="Yes","❌ Disc",IF(Y7="No","⚠ Missing",IF(AB7="Yes","✓ OK","⚠ Check")))) -> ✓ OK | AF7: 18-09-2026 | AG7: Sunil CR | AH7: Yes | AI7: No | AJ7: Good finish | AK7: Yes | AM7: No | AN7: =IF(AF7="","",IF(AI7="Yes","❌ Disc",IF(AH7="No","⚠ Missing",IF(AK7="Yes","✓ OK","⚠ Check")))) -> ✓ OK | AW7: =IF(AO7="","",IF(AR7="Yes","❌ Disc",IF(AQ7="No","⚠ Missing",IF(AT7="Yes","✓ OK","⚠ Check"))))
